Workbook

Sheet 路线图仪表盘
A1: Vision Demo 路线图仪表盘
A2: 数据自动汇总自“全部功能路线图”。请在主表维护状态、优先级、计划版本和负责人。
B4: 功能总数 | E4: 已完成 | H4: P0／P1 | K4: 待认领
B5: =COUNTA('全部功能路线图'!$A$5:$A$84) | E5: =COUNTIF('全部功能路线图'!$L$5:$L$84,"已完成") | H5: =COUNTIF('全部功能路线图'!$K$5:$K$84,"P0")+COUNTIF('全部功能路线图'!$K$5:$K$84,"P1") | K5: =COUNTIF('全部功能路线图'!$Q$5:$Q$84,"待认领")
B9: 状态分布 | E9: 模块分布
B10: 待评估 | C10: =COUNTIF('全部功能路线图'!$L$5:$L$84,B10) | E10: 基础体验 | F10: =COUNTIF('全部功能路线图'!$B$5:$B$84,E10)
B11: 已规划 | C11: =COUNTIF('全部功能路线图'!$L$5:$L$84,B11) | E11: 协作推广 | F11: =COUNTIF('全部功能路线图'!$B$5:$B$84,E11)
B12: 设计中 | C12: =COUNTIF('全部功能路线图'!$L$5:$L$84,B12) | E12: 项目协作 | F12: =COUNTIF('全部功能路线图'!$B$5:$B$84,E12)
B13: 开发中 | C13: =COUNTIF('全部功能路线图'!$L$5:$L$84,B13) | E13: 需求管理 | F13: =COUNTIF('全部功能路线图'!$B$5:$B$84,E13)
B14: 待验收 | C14: =COUNTIF('全部功能路线图'!$L$5:$L$84,B14) | E14: 代码仓库 | F14: =COUNTIF('全部功能路线图'!$B$5:$B$84,E14)
B15: 已完成 | C15: =COUNTIF('全部功能路线图'!$L$5:$L$84,B15) | E15: 代码质量 | F15: =COUNTIF('全部功能路线图'!$B$5:$B$84,E15)
B16: 已暂停 | C16: =COUNTIF('全部功能路线图'!$L$5:$L$84,B16) | E16: 流水线 | F16: =COUNTIF('全部功能路线图'!$B$5:$B$84,E16)
B17: 不采纳 | C17: =COUNTIF('全部功能路线图'!$L$5:$L$84,B17) | E17: 制品管理 | F17: =COUNTIF('全部功能路线图'!$B$5:$B$84,E17)
E18: 部署管理 | F18: =COUNTIF('全部功能路线图'!$B$5:$B$84,E18)
E19: 测试管理 | F19: =COUNTIF('全部功能路线图'!$B$5:$B$84,E19)
B22: 首轮评审建议
B23: 1. 先确认 P0 主路径是否覆盖部门沟通需要。
B24: 2. 将“待认领”条目分配到角色或具体负责人。
B25: 3. 将确认后的日期从“建议排期”改为“已确认”。
B26: 4. 对每个 v0.2 条目补齐设计稿和验收人。
B27: 5. 双周复盘一次状态、阻塞与范围边界。

Sheet 全部功能路线图
A1: Vision Demo 全部功能路线图 v0.1
A2: 初版依据当前代码、导航和已实现页面整理。未来日期均为建议节奏，只有“排期状态=已确认”才视为正式承诺；实现边界默认面向 Demo 模拟，不代表建设真实业务后端。
A4: 功能编号 | B4: 一级模块 | C4: 二级模块 | D4: 功能名称 | E4: 类型 | F4: 核心演示路径 | G4: 实现边界 | H4: 使用场景与价值 | I4: 需求来源 | J4: 需求部门 | K4: 优先级 | L4: 状态 | M4: 当前成熟度 | N4: 目标成熟度 | O4: 当前实现说明 | P4: 下一步动作 | Q4: 负责人 | R4: 协作角色 | S4: 计划版本 | T4: 排期状态 | U4: 目标完成时间 | V4: 设计稿 | W4: Demo 入口 | X4: 验收标准 | Y4: 依赖与风险 | Z4: 最新进展／阻塞项 | AA4: 验收结果 | AB4: 实际完成时间 | AC4: 最后更新时间
A5: DEMO-001 | B5: 基础体验 | C5: 应用框架 | D5: 项目级应用壳层与导航 | E5: 现有能力 | F5: 是 | G5: UI 交互 + 数据联动 | H5: 让不同部门在统一的信息架构中定位项目与研发活动。 | I5: 现有 Demo 实现 | J5: 产品、研发、设计 | K5: P0 | L5: 已完成 | M5: L3 数据联动 | N5: L3 数据联动 | O5: 已完成页面、关键交互和示例数据联动。 | P5: 纳入回归清单，持续根据部门反馈微调。 | Q5: Demo 小组 | R5: 产品、设计、前端 | S5: v0.1 | T5: 已确认 | U5: 46246 | W5: http://127.0.0.1:5173/demo/#/projects/lighting/overview | X5: 页面可稳定访问；主要交互可操作；刷新和页面跳转后数据语义一致。 | Y5: 需防止后续修改破坏跨页面数据一致性。 | Z5: 已完成并通过本地类型、构建与页面回归。 | AA5: 通过 | AB5: 46246 | AC5: 46246
A6: DEMO-002 | B6: 基础体验 | C6: 项目切换 | D6: 多项目切换与导航状态保持 | E6: 现有能力 | F6: 否 | G6: UI 交互 + 数据联动 | H6: 演示同一套能力在不同项目上下文中的复用。 | I6: 现有 Demo 实现 | J6: 产品、研发、设计 | K6: P1 | L6: 已完成 | M6: L3 数据联动 | N6: L3 数据联动 | O6: 已完成页面、关键交互和示例数据联动。 | P6: 纳入回归清单，持续根据部门反馈微调。 | Q6: Demo 小组 | R6: 产品、设计、前端 | S6: v0.1 | T6: 已确认 | U6: 46246 | W6: http://127.0.0.1:5173/demo/#/projects/lighting/overview | X6: 页面可稳定访问；主要交互可操作；刷新和页面跳转后数据语义一致。 | Y6: 需防止后续修改破坏跨页面数据一致性。 | Z6: 已完成并通过本地类型、构建与页面回归。 | AA6: 通过 | AB6: 46246 | AC6: 46246
A7: DEMO-003 | B7: 基础体验 | C7: 主题 | D7: 浅色／深色主题切换 | E7: 现有能力 | F7: 否 | G7: UI 交互 + 数据联动 | H7: 验证设计系统变量和组件在双主题下的一致性。 | I7: 现有 Demo 实现 | J7: 产品、研发、设计 | K7: P1 | L7: 已完成 | M7: L3 数据联动 | N7: L3 数据联动 | O7: 已完成页面、关键交互和示例数据联动。 | P7: 纳入回归清单，持续根据部门反馈微调。 | Q7: Demo 小组 | R7: 产品、设计、前端 | S7: v0.1 | T7: 已确认 | U7: 46246 | W7: http://127.0.0.1:5173/demo/#/projects/lighting/overview | X7: 页面可稳定访问；主要交互可操作；刷新和页面跳转后数据语义一致。 | Y7: 需防止后续修改破坏跨页面数据一致性。 | Z7: 已完成并通过本地类型、构建与页面回归。 | AA7: 通过 | AB7: 46246 | AC7: 46246
A8: DEMO-004 | B8: 基础体验 | C8: 路由 | D8: 关键页面深链接 | E8: 现有能力 | F8: 是 | G8: UI 交互 + 数据联动 | H8: 会议和异步沟通时可直接分享具体功能页面。 | I8: 现有 Demo 实现 | J8: 产品、研发、设计 | K8: P0 | L8: 已完成 | M8: L3 数据联动 | N8: L3 数据联动 | O8: 已完成页面、关键交互和示例数据联动。 | P8: 纳入回归清单，持续根据部门反馈微调。 | Q8: Demo 小组 | R8: 产品、设计、前端 | S8: v0.1 | T8: 已确认 | U8: 46246 | W8: http://127.0.0.1:5173/demo/#/projects/lighting/code/repositories/flight-control-core | X8: 页面可稳定访问；主要交互可操作；刷新和页面跳转后数据语义一致。 | Y8: 需防止后续修改破坏跨页面数据一致性。 | Z8: 已完成并通过本地类型、构建与页面回归。 | AA8: 通过 | AB8: 46246 | AC8: 46246
A9: DEMO-005 | B9: 基础体验 | C9: 全局搜索 | D9: 跨模块全局搜索 | E9: 新功能 | F9: 否 | G9: Demo 模拟 | H9: 通过一个入口快速定位仓库、需求、流水线、应用与测试对象。 | I9: 跨部门推广规划 | J9: 产品、研发 | K9: P1 | L9: 已规划 | M9: L0 占位可达 | N9: L3 数据联动 | O9: 当前导航可达，使用通用占位页面。 | P9: 补齐关键场景、示例数据和核心交互。 | Q9: 待认领 | R9: 产品、设计、前端 | S9: v0.3 | T9: 建议排期 | U9: 46283 | W9: http://127.0.0.1:5173/demo/#/projects/lighting/overview | X9: 可从导航进入；核心信息完整；关键交互可操作；数据在相关页面间保持一致。 | Y9: 需确认部门共识与设计稿；仅模拟核心流程，不建设真实后端。 | Z9: 待评审范围与负责人。 | AA9: 未开始 | AC9: 46246
A10: DEMO-006 | B10: 基础体验 | C10: 通知 | D10: 通知中心与待办提示 | E10: 新功能 | F10: 否 | G10: Demo 模拟 | H10: 模拟评审、流水线失败、部署完成等跨模块提醒。 | I10: 跨部门推广规划 | J10: 产品、研发、测试、运维 | K10: P2 | L10: 已规划 | M10: L0 占位可达 | N10: L3 数据联动 | O10: 当前导航可达，使用通用占位页面。 | P10: 补齐关键场景、示例数据和核心交互。 | Q10: 待认领 | R10: 产品、设计、前端 | S10: v0.4 | T10: 建议排期 | U10: 46311 | X10: 可从导航进入；核心信息完整；关键交互可操作；数据在相关页面间保持一致。 | Y10: 需确认部门共识与设计稿；仅模拟核心流程，不建设真实后端。 | Z10: 待评审范围与负责人。 | AA10: 未开始 | AC10: 46246
A11: DEMO-007 | B11: 基础体验 | C11: 响应式 | D11: 常用桌面分辨率适配 | E11: 体验优化 | F11: 否 | G11: Demo 模拟 | H11: 保证会议室大屏、笔记本和小屏窗口下都可顺畅演示。 | I11: 跨部门推广规划 | J11: 全体部门 | K11: P1 | L11: 已规划 | M11: L2 可交互 | N11: L3 数据联动 | O11: 核心仓库页面已有小屏优化，但尚未形成统一回归矩阵。 | P11: 补齐关键场景、示例数据和核心交互。 | Q11: 待认领 | R11: 产品、设计、前端 | S11: v0.2 | T11: 建议排期 | U11: 46262 | W11: http://127.0.0.1:5173/demo/#/projects/lighting/code/repositories/flight-control-core | X11: 可从导航进入；核心信息完整；关键交互可操作；数据在相关页面间保持一致。 | Y11: 需确认部门共识与设计稿；仅模拟核心流程，不建设真实后端。 | Z11: 待评审范围与负责人。 | AA11: 未开始 | AC11: 46246
A12: DEMO-008 | B12: 基础体验 | C12: 无障碍 | D12: 键盘与可访问性基线 | E12: 体验优化 | F12: 否 | G12: Demo 模拟 | H12: 降低演示操作门槛，并保证组件语义与焦点状态一致。 | I12: 跨部门推广规划 | J12: 产品、研发 | K12: P2 | L12: 已规划 | M12: L0 占位可达 | N12: L3 数据联动 | O12: 当前导航可达，使用通用占位页面。 | P12: 补齐关键场景、示例数据和核心交互。 | Q12: 待认领 | R12: 产品、设计、前端 | S12: v0.4 | T12: 建议排期 | U12: 46311 | X12: 可从导航进入；核心信息完整；关键交互可操作；数据在相关页面间保持一致。 | Y12: 需确认部门共识与设计稿；仅模拟核心流程，不建设真实后端。 | Z12: 待评审范围与负责人。 | AA12: 未开始 | AC12: 46246
A13: DEMO-009 | B13: 基础体验 | C13: 数据治理 | D13: 统一轻量示例数据源 | E13: 现有能力 | F13: 是 | G13: UI 交互 + 数据联动 | H13: 让仓库、提交、分支、标签和合并请求呈现同一真实叙事。 | I13: 现有 Demo 实现 | J13: 产品、研发、设计 | K13: P0 | L13: 已完成 | M13: L3 数据联动 | N13: L3 数据联动 | O13: 所有示例仓库已指向统一数据模型，计数和关联关系由数据计算。 | P13: 纳入回归清单，持续根据部门反馈微调。 | Q13: Demo 小组 | R13: 产品、设计、前端 | S13: v0.1 | T13: 已确认 | U13: 46246 | W13: http://127.0.0.1:5173/demo/#/projects/lighting/code/repositories/flight-control-core | X13: 页面可稳定访问；主要交互可操作；刷新和页面跳转后数据语义一致。 | Y13: 需防止后续修改破坏跨页面数据一致性。 | Z13: 已完成并通过本地类型、构建与页面回归。 | AA13: 通过 | AB13: 46246 | AC13: 46246
A14: DEMO-010 | B14: 协作推广 | C14: 反馈闭环 | D14: 部门反馈收集与回链 | E14: 协作治理 | F14: 否 | G14: Demo 模拟 | H14: 让使用者从页面问题快速回链到路线图条目和设计稿。 | I14: 跨部门推广规划 | J14: 全体部门 | K14: P0 | L14: 已规划 | M14: L0 占位可达 | N14: L2 可交互 | O14: 当前导航可达，使用通用占位页面。 | P14: 补齐关键场景、示例数据和核心交互。 | Q14: Demo 运营 | R14: 产品、设计、研发代表 | S14: v0.2 | T14: 建议排期 | U14: 46262 | X14: 提供统一反馈入口；每条反馈可关联功能编号、页面、截图、提出部门与处理状态。 | Y14: 需确认部门共识与设计稿；仅模拟核心流程，不建设真实后端。 | Z14: 待评审范围与负责人。 | AA14: 未开始 | AC14: 46246
A15: DEMO-011 | B15: 协作推广 | C15: 变更沟通 | D15: 版本更新日志 | E15: 协作治理 | F15: 否 | G15: Demo 模拟 | H15: 让部门清楚每次更新新增了什么、调整了什么、是否影响既有演示路径。 | I15: 跨部门推广规划 | J15: 全体部门 | K15: P1 | L15: 已规划 | M15: L0 占位可达 | N15: L2 可交互 | O15: 当前导航可达，使用通用占位页面。 | P15: 补齐关键场景、示例数据和核心交互。 | Q15: Demo 运营 | R15: 产品、设计、前端 | S15: v0.2 | T15: 建议排期 | U15: 46262 | X15: 可从导航进入；核心信息完整；关键交互可操作；数据在相关页面间保持一致。 | Y15: 需确认部门共识与设计稿；仅模拟核心流程，不建设真实后端。 | Z15: 待评审范围与负责人。 | AA15: 未开始 | AC15: 46246
A16: DEMO-012 | B16: 协作推广 | C16: 使用支持 | D16: Demo 使用指南与讲解脚本 | E16: 内容补充 | F16: 否 | G16: Demo 模拟 | H16: 帮助非建设人员独立完成核心场景演示。 | I16: 跨部门推广规划 | J16: 全体部门 | K16: P1 | L16: 已规划 | M16: L0 占位可达 | N16: L2 可交互 | O16: 当前导航可达，使用通用占位页面。 | P16: 补齐关键场景、示例数据和核心交互。 | Q16: 产品 | R16: 产品、设计、业务代表 | S16: v0.2 | T16: 建议排期 | U16: 46262 | X16: 可从导航进入；核心信息完整；关键交互可操作；数据在相关页面间保持一致。 | Y16: 需确认部门共识与设计稿；仅模拟核心流程，不建设真实后端。 | Z16: 待评审范围与负责人。 | AA16: 未开始 | AC16: 46246
A17: DEMO-013 | B17: 项目协作 | C17: 项目概览 | D17: 项目概览仪表盘 | E17: 现有能力 | F17: 否 | G17: 静态展示 + 局部交互 | H17: 用需求、流水线、缺陷和环境指标建立项目全局认知。 | I17: 现有 Demo 实现 | J17: 产品、研发、设计 | K17: P1 | L17: 已完成 | M17: L3 数据联动 | N17: L3 数据联动 | O17: 已完成页面、关键交互和示例数据联动。 | P17: 纳入回归清单，持续根据部门反馈微调。 | Q17: Demo 小组 | R17: 产品、设计、前端 | S17: v0.1 | T17: 已确认 | U17: 46246 | W17: http://127.0.0.1:5173/demo/#/projects/lighting/overview | X17: 页面可稳定访问；主要交互可操作；刷新和页面跳转后数据语义一致。 | Y17: 需防止后续修改破坏跨页面数据一致性。 | Z17: 已完成并通过本地类型、构建与页面回归。 | AA17: 通过 | AB17: 46246 | AC17: 46246
A18: DEMO-014 | B18: 项目协作 | C18: 项目管理 | D18: 项目管理总览 | E18: 新功能 | F18: 否 | G18: Demo 模拟 | H18: 集中展示项目成员、迭代、里程碑和近期活动。 | I18: 跨部门推广规划 | J18: 产品、项目管理、研发 | K18: P2 | L18: 已规划 | M18: L0 占位可达 | N18: L3 数据联动 | O18: 当前导航可达，使用通用占位页面。 | P18: 补齐关键场景、示例数据和核心交互。 | Q18: 待认领 | R18: 产品、设计、前端 | S18: v0.4 | T18: 建议排期 | U18: 46311 | W18: http://127.0.0.1:5173/demo/#/projects/lighting/management | X18: 可从导航进入；核心信息完整；关键交互可操作；数据在相关页面间保持一致。 | Y18: 需确认部门共识与设计稿；仅模拟核心流程，不建设真实后端。 | Z18: 待评审范围与负责人。 | AA18: 未开始 | AC18: 46246
A19: DEMO-015 | B19: 项目协作 | C19: 项目管理 | D19: 成员与角色 | E19: 新功能 | F19: 否 | G19: Demo 模拟 | H19: 模拟项目成员、角色和职责分工，支撑跨部门协作讨论。 | I19: 跨部门推广规划 | J19: 项目管理、研发 | K19: P3 | L19: 已规划 | M19: L0 占位可达 | N19: L3 数据联动 | O19: 当前导航可达，使用通用占位页面。 | P19: 补齐关键场景、示例数据和核心交互。 | Q19: 待认领 | R19: 产品、设计、前端 | S19: v1.0 | T19: 建议排期 | U19: 46325 | X19: 可从导航进入；核心信息完整；关键交互可操作；数据在相关页面间保持一致。 | Y19: 需确认部门共识与设计稿；仅模拟核心流程，不建设真实后端。 | Z19: 待评审范围与负责人。 | AA19: 未开始 | AC19: 46246
A20: DEMO-016 | B20: 项目协作 | C20: 项目管理 | D20: 迭代与里程碑 | E20: 新功能 | F20: 否 | G20: Demo 模拟 | H20: 用统一时间轴连接需求、研发、测试和发布计划。 | I20: 跨部门推广规划 | J20: 产品、项目管理、研发、测试 | K20: P1 | L20: 已规划 | M20: L0 占位可达 | N20: L3 数据联动 | O20: 当前导航可达，使用通用占位页面。 | P20: 补齐关键场景、示例数据和核心交互。 | Q20: 待认领 | R20: 产品、设计、前端 | S20: v0.4 | T20: 建议排期 | U20: 46311 | X20: 可从导航进入；核心信息完整；关键交互可操作；数据在相关页面间保持一致。 | Y20: 需确认部门共识与设计稿；仅模拟核心流程，不建设真实后端。 | Z20: 待评审范围与负责人。 | AA20: 未开始 | AC20: 46246
A21: DEMO-017 | B21: 需求管理 | C21: 需求列表 | D21: 需求列表与筛选 | E21: 新功能 | F21: 否 | G21: Demo 模拟 | H21: 按状态、负责人、优先级和迭代浏览需求。 | I21: 跨部门推广规划 | J21: 产品、研发、测试 | K21: P1 | L21: 已规划 | M21: L0 占位可达 | N21: L3 数据联动 | O21: 当前导航可达，使用通用占位页面。 | P21: 补齐关键场景、示例数据和核心交互。 | Q21: 待认领 | R21: 产品、设计、前端 | S21: v0.3 | T21: 建议排期 | U21: 46283 | W21: http://127.0.0.1:5173/demo/#/projects/lighting/requirements | X21: 可从导航进入；核心信息完整；关键交互可操作；数据在相关页面间保持一致。 | Y21: 需确认部门共识与设计稿；仅模拟核心流程，不建设真实后端。 | Z21: 待评审范围与负责人。 | AA21: 未开始 | AC21: 46246
A22: DEMO-018 | B22: 需求管理 | C22: 需求详情 | D22: 需求详情与状态流转 | E22: 新功能 | F22: 否 | G22: Demo 模拟 | H22: 围绕一个需求展示描述、负责人、验收标准和协作记录。 | I22: 跨部门推广规划 | J22: 产品、研发、测试 | K22: P1 | L22: 已规划 | M22: L0 占位可达 | N22: L3 数据联动 | O22: 当前导航可达，使用通用占位页面。 | P22: 补齐关键场景、示例数据和核心交互。 | Q22: 待认领 | R22: 产品、设计、前端 | S22: v0.3 | T22: 建议排期 | U22: 46283 | X22: 可从导航进入；核心信息完整；关键交互可操作；数据在相关页面间保持一致。 | Y22: 需确认部门共识与设计稿；仅模拟核心流程，不建设真实后端。 | Z22: 待评审范围与负责人。 | AA22: 未开始 | AC22: 46246
A23: DEMO-019 | B23: 需求管理 | C23: 追溯关系 | D23: 需求—代码—测试—发布追溯 | E23: 新功能 | F23: 是 | G23: Demo 模拟 | H23: 展示需求如何关联提交、合并请求、测试结果和发布版本。 | I23: 跨部门推广规划 | J23: 产品、研发、测试、质量 | K23: P0 | L23: 已规划 | M23: L0 占位可达 | N23: L4 端到端叙事 | O23: 当前导航可达，使用通用占位页面。 | P23: 补齐关键场景、示例数据和核心交互。 | Q23: 待认领 | R23: 产品、设计、前端 | S23: v1.0 | T23: 建议排期 | U23: 46325 | X23: 从需求详情可进入关联提交、合并请求、测试结果和发布记录；对象编号与状态一致。 | Y23: 需确认部门共识与设计稿；仅模拟核心流程，不建设真实后端。 | Z23: 待评审范围与负责人。 | AA23: 未开始 | AC23: 46246
A24: DEMO-020 | B24: 项目协作 | C24: 项目设置 | D24: 项目属性、通知与权限展示 | E24: 新功能 | F24: 否 | G24: Demo 模拟 | H24: 支持讨论项目级配置和治理策略。 | I24: 跨部门推广规划 | J24: 项目管理、研发管理 | K24: P3 | L24: 已规划 | M24: L0 占位可达 | N24: L3 数据联动 | O24: 当前导航可达，使用通用占位页面。 | P24: 补齐关键场景、示例数据和核心交互。 | Q24: 待认领 | R24: 产品、设计、前端 | S24: v1.0 | T24: 建议排期 | U24: 46325 | W24: http://127.0.0.1:5173/demo/#/projects/lighting/settings | X24: 可从导航进入；核心信息完整；关键交互可操作；数据在相关页面间保持一致。 | Y24: 需确认部门共识与设计稿；仅模拟核心流程，不建设真实后端。 | Z24: 待评审范围与负责人。 | AA24: 未开始 | AC24: 46246
A25: DEMO-021 | B25: 代码仓库 | C25: 仓库列表 | D25: 仓库目录与层级列表 | E25: 现有能力 | F25: 是 | G25: UI 交互 + 数据联动 | H25: 浏览组织、分组和仓库层级，快速进入目标仓库。 | I25: 现有 Demo 实现 | J25: 产品、研发、设计 | K25: P0 | L25: 已完成 | M25: L3 数据联动 | N25: L3 数据联动 | O25: 已完成页面、关键交互和示例数据联动。 | P25: 纳入回归清单，持续根据部门反馈微调。 | Q25: Demo 小组 | R25: 产品、设计、前端 | S25: v0.1 | T25: 已确认 | U25: 46246 | W25: http://127.0.0.1:5173/demo/#/projects/lighting/code/repositories | X25: 页面可稳定访问；主要交互可操作；刷新和页面跳转后数据语义一致。 | Y25: 需防止后续修改破坏跨页面数据一致性。 | Z25: 已完成并通过本地类型、构建与页面回归。 | AA25: 通过 | AB25: 46246 | AC25: 46246
A26: DEMO-022 | B26: 代码仓库 | C26: 仓库列表 | D26: 仓库关键字搜索与排序 | E26: 现有能力 | F26: 否 | G26: UI 交互 + 数据联动 | H26: 在多仓库场景下快速定位目标。 | I26: 现有 Demo 实现 | J26: 产品、研发、设计 | K26: P1 | L26: 已完成 | M26: L3 数据联动 | N26: L3 数据联动 | O26: 已完成页面、关键交互和示例数据联动。 | P26: 纳入回归清单，持续根据部门反馈微调。 | Q26: Demo 小组 | R26: 产品、设计、前端 | S26: v0.1 | T26: 已确认 | U26: 46246 | W26: http://127.0.0.1:5173/demo/#/projects/lighting/code/repositories | X26: 页面可稳定访问；主要交互可操作；刷新和页面跳转后数据语义一致。 | Y26: 需防止后续修改破坏跨页面数据一致性。 | Z26: 已完成并通过本地类型、构建与页面回归。 | AA26: 通过 | AB26: 46246 | AC26: 46246
A27: DEMO-023 | B27: 代码仓库 | C27: 仓库列表 | D27: 高级筛选与收藏视图 | E27: 新功能 | F27: 否 | G27: Demo 模拟 | H27: 按语言、活跃度、负责人、收藏状态筛选仓库。 | I27: 跨部门推广规划 | J27: 产品、研发 | K27: P2 | L27: 已规划 | M27: L1 静态展示 | N27: L2 可交互 | O27: 已预留筛选和设置入口，部分按钮仍为禁用演示态。 | P27: 补齐关键场景、示例数据和核心交互。 | Q27: 待认领 | R27: 产品、设计、前端 | S27: v0.3 | T27: 建议排期 | U27: 46283 | W27: http://127.0.0.1:5173/demo/#/projects/lighting/code/repositories | X27: 可从导航进入；核心信息完整；关键交互可操作；数据在相关页面间保持一致。 | Y27: 需确认部门共识与设计稿；仅模拟核心流程，不建设真实后端。 | Z27: 待评审范围与负责人。 | AA27: 未开始 | AC27: 46246
A28: DEMO-024 | B28: 代码仓库 | C28: 仓库创建 | D28: 新建／导入仓库弹窗 | E28: 新功能 | F28: 否 | G28: Demo 模拟 | H28: 完整演示从代码仓库入口创建或导入仓库的流程。 | I28: 跨部门推广规划 | J28: 产品、研发 | K28: P2 | L28: 已规划 | M28: L0 占位可达 | N28: L2 可交互 | O28: 当前导航可达，使用通用占位页面。 | P28: 补齐关键场景、示例数据和核心交互。 | Q28: 待认领 | R28: 产品、设计、前端 | S28: v0.3 | T28: 建议排期 | U28: 46283 | W28: http://127.0.0.1:5173/demo/#/projects/lighting/code/repositories | X28: 点击新建仓库可打开表单；确认后新增一条本地示例仓库并给出成功反馈；无需真实 Git 服务。 | Y28: 需确认部门共识与设计稿；仅模拟核心流程，不建设真实后端。 | Z28: 待评审范围与负责人。 | AA28: 未开始 | AC28: 46246
A29: DEMO-025 | B29: 代码仓库 | C29: 仓库浏览 | D29: 文件树、目录与文件内容浏览 | E29: 现有能力 | F29: 是 | G29: UI 交互 + 数据联动 | H29: 模拟真实仓库的日常代码阅读路径。 | I29: 现有 Demo 实现 | J29: 产品、研发、设计 | K29: P0 | L29: 已完成 | M29: L3 数据联动 | N29: L3 数据联动 | O29: 已完成页面、关键交互和示例数据联动。 | P29: 纳入回归清单，持续根据部门反馈微调。 | Q29: Demo 小组 | R29: 产品、设计、前端 | S29: v0.1 | T29: 已确认 | U29: 46246 | W29: http://127.0.0.1:5173/demo/#/projects/lighting/code/repositories/flight-control-core | X29: 页面可稳定访问；主要交互可操作；刷新和页面跳转后数据语义一致。 | Y29: 需防止后续修改破坏跨页面数据一致性。 | Z29: 已完成并通过本地类型、构建与页面回归。 | AA29: 通过 | AB29: 46246 | AC29: 46246
A30: DEMO-026 | B30: 代码仓库 | C30: 仓库浏览 | D30: 分支／标签切换下拉框 | E30: 现有能力 | F30: 是 | G30: UI 交互 + 数据联动 | H30: 切换引用后文件、提交和计数同步变化。 | I30: 现有 Demo 实现 | J30: 产品、研发、设计 | K30: P0 | L30: 已完成 | M30: L3 数据联动 | N30: L3 数据联动 | O30: 已完成页面、关键交互和示例数据联动。 | P30: 纳入回归清单，持续根据部门反馈微调。 | Q30: Demo 小组 | R30: 产品、设计、前端 | S30: v0.1 | T30: 已确认 | U30: 46246 | V30: https://www.figma.com/design/AH5UD6NGdbtqy2z4o9k7QW/%E8%BD%AF%E4%BB%B6%E5%B7%A5%E5%8E%82?node-id=524-35227 | W30: http://127.0.0.1:5173/demo/#/projects/lighting/code/repositories/flight-control-core | X30: 页面可稳定访问；主要交互可操作；刷新和页面跳转后数据语义一致。 | Y30: 需防止后续修改破坏跨页面数据一致性。 | Z30: 已完成并通过本地类型、构建与页面回归。 | AA30: 通过 | AB30: 46246 | AC30: 46246
A31: DEMO-027 | B31: 代码仓库 | C31: 仓库浏览 | D31: 代码克隆下拉框 | E31: 现有能力 | F31: 否 | G31: UI 交互 + 数据联动 | H31: 展示 SSH／HTTP 克隆地址并支持复制。 | I31: 现有 Demo 实现 | J31: 产品、研发、设计 | K31: P1 | L31: 已完成 | M31: L3 数据联动 | N31: L3 数据联动 | O31: 已完成页面、关键交互和示例数据联动。 | P31: 纳入回归清单，持续根据部门反馈微调。 | Q31: Demo 小组 | R31: 产品、设计、前端 | S31: v0.1 | T31: 已确认 | U31: 46246 | V31: https://www.figma.com/design/AH5UD6NGdbtqy2z4o9k7QW/%E8%BD%AF%E4%BB%B6%E5%B7%A5%E5%8E%82?node-id=524-35243 | W31: http://127.0.0.1:5173/demo/#/projects/lighting/code/repositories/flight-control-core | X31: 页面可稳定访问；主要交互可操作；刷新和页面跳转后数据语义一致。 | Y31: 需防止后续修改破坏跨页面数据一致性。 | Z31: 已完成并通过本地类型、构建与页面回归。 | AA31: 通过 | AB31: 46246 | AC31: 46246
A32: DEMO-028 | B32: 代码仓库 | C32: 文件详情 | D32: 打开文件—代码内容 | E32: 现有能力 | F32: 是 | G32: UI 交互 + 数据联动 | H32: 查看文件名称、大小、内容和操作区。 | I32: 现有 Demo 实现 | J32: 产品、研发、设计 | K32: P0 | L32: 已完成 | M32: L3 数据联动 | N32: L3 数据联动 | O32: 已完成页面、关键交互和示例数据联动。 | P32: 纳入回归清单，持续根据部门反馈微调。 | Q32: Demo 小组 | R32: 产品、设计、前端 | S32: v0.1 | T32: 已确认 | U32: 46246 | W32: http://127.0.0.1:5173/demo/#/projects/lighting/code/repositories/flight-control-core | X32: 页面可稳定访问；主要交互可操作；刷新和页面跳转后数据语义一致。 | Y32: 需防止后续修改破坏跨页面数据一致性。 | Z32: 已完成并通过本地类型、构建与页面回归。 | AA32: 通过 | AB32: 46246 | AC32: 46246
A33: DEMO-029 | B33: 代码仓库 | C33: 文件详情 | D33: 打开文件—修改追溯 | E33: 现有能力 | F33: 是 | G33: UI 交互 + 数据联动 | H33: 按提交与作者展示逐行归属，模拟 blame 场景。 | I33: 现有 Demo 实现 | J33: 产品、研发、设计 | K33: P0 | L33: 已完成 | M33: L3 数据联动 | N33: L3 数据联动 | O33: 已完成页面、关键交互和示例数据联动。 | P33: 纳入回归清单，持续根据部门反馈微调。 | Q33: Demo 小组 | R33: 产品、设计、前端 | S33: v0.1 | T33: 已确认 | U33: 46246 | V33: https://www.figma.com/design/AH5UD6NGdbtqy2z4o9k7QW/%E8%BD%AF%E4%BB%B6%E5%B7%A5%E5%8E%82?node-id=475-4006 | W33: http://127.0.0.1:5173/demo/#/projects/lighting/code/repositories/flight-control-core | X33: 页面可稳定访问；主要交互可操作；刷新和页面跳转后数据语义一致。 | Y33: 需防止后续修改破坏跨页面数据一致性。 | Z33: 已完成并通过本地类型、构建与页面回归。 | AA33: 通过 | AB33: 46246 | AC33: 46246
A34: DEMO-030 | B34: 代码仓库 | C34: 文件详情 | D34: 打开文件—文件历史 | E34: 现有能力 | F34: 是 | G34: UI 交互 + 数据联动 | H34: 以提交项展示当前文件的修改历史。 | I34: 现有 Demo 实现 | J34: 产品、研发、设计 | K34: P0 | L34: 已完成 | M34: L3 数据联动 | N34: L3 数据联动 | O34: 已完成页面、关键交互和示例数据联动。 | P34: 纳入回归清单，持续根据部门反馈微调。 | Q34: Demo 小组 | R34: 产品、设计、前端 | S34: v0.1 | T34: 已确认 | U34: 46246 | V34: https://www.figma.com/design/AH5UD6NGdbtqy2z4o9k7QW/%E8%BD%AF%E4%BB%B6%E5%B7%A5%E5%8E%82?node-id=524-35732 | W34: http://127.0.0.1:5173/demo/#/projects/lighting/code/repositories/flight-control-core | X34: 页面可稳定访问；主要交互可操作；刷新和页面跳转后数据语义一致。 | Y34: 需防止后续修改破坏跨页面数据一致性。 | Z34: 已完成并通过本地类型、构建与页面回归。 | AA34: 通过 | AB34: 46246 | AC34: 46246
A35: DEMO-031 | B35: 代码仓库 | C35: 文件详情 | D35: 文件差异对比 | E35: 新功能 | F35: 是 | G35: Demo 模拟 | H35: 从文件历史或提交详情进入新旧版本 diff，辅助评审沟通。 | I35: 跨部门推广规划 | J35: 产品、研发 | K35: P0 | L35: 已规划 | M35: L0 占位可达 | N35: L3 数据联动 | O35: 当前导航可达，使用通用占位页面。 | P35: 补齐关键场景、示例数据和核心交互。 | Q35: 待认领 | R35: 产品、设计、前端 | S35: v0.2 | T35: 建议排期 | U35: 46262 | X35: 可选择两个版本；展示增删行语义色、文件路径和提交信息；复用 Code Experience 组件。 | Y35: 需确认部门共识与设计稿；仅模拟核心流程，不建设真实后端。 | Z35: 待评审范围与负责人。 | AA35: 未开始 | AC35: 46246
A36: DEMO-032 | B36: 代码仓库 | C36: 文件详情 | D36: 仓库内代码搜索 | E36: 新功能 | F36: 否 | G36: Demo 模拟 | H36: 按文件名或内容快速定位代码片段。 | I36: 跨部门推广规划 | J36: 产品、研发 | K36: P2 | L36: 已规划 | M36: L0 占位可达 | N36: L3 数据联动 | O36: 当前导航可达，使用通用占位页面。 | P36: 补齐关键场景、示例数据和核心交互。 | Q36: 待认领 | R36: 产品、设计、前端 | S36: v0.3 | T36: 建议排期 | U36: 46283 | X36: 可从导航进入；核心信息完整；关键交互可操作；数据在相关页面间保持一致。 | Y36: 需确认部门共识与设计稿；仅模拟核心流程，不建设真实后端。 | Z36: 待评审范围与负责人。 | AA36: 未开始 | AC36: 46246
A37: DEMO-033 | B37: 代码仓库 | C37: 文件详情 | D37: 编辑、上传与下载演示 | E37: 新功能 | F37: 否 | G37: Demo 模拟 | H37: 展示常见文件操作入口及成功反馈，但不写入真实仓库。 | I37: 跨部门推广规划 | J37: 产品、研发 | K37: P3 | L37: 待评估 | M37: L0 占位可达 | N37: L2 可交互 | O37: 当前导航可达，使用通用占位页面。 | P37: 补齐关键场景、示例数据和核心交互。 | Q37: 待认领 | R37: 产品、设计、前端 | S37: v1.0 | T37: 建议排期 | U37: 46325 | X37: 可从导航进入；核心信息完整；关键交互可操作；数据在相关页面间保持一致。 | Y37: 需要明确哪些写操作值得模拟，避免让使用者误认为已接入真实 Git。 | Z37: 待评审范围与负责人。 | AA37: 未开始 | AC37: 46246
A38: DEMO-034 | B38: 代码仓库 | C38: 提交 | D38: 提交列表、筛选与描述展开 | E38: 现有能力 | F38: 是 | G38: UI 交互 + 数据联动 | H38: 按分支和日期查看提交，展开描述并复制提交号。 | I38: 现有 Demo 实现 | J38: 产品、研发、设计 | K38: P0 | L38: 已完成 | M38: L3 数据联动 | N38: L3 数据联动 | O38: 已完成页面、关键交互和示例数据联动。 | P38: 纳入回归清单，持续根据部门反馈微调。 | Q38: Demo 小组 | R38: 产品、设计、前端 | S38: v0.1 | T38: 已确认 | U38: 46246 | V38: https://www.figma.com/design/AH5UD6NGdbtqy2z4o9k7QW/%E8%BD%AF%E4%BB%B6%E5%B7%A5%E5%8E%82?node-id=486-5192 | W38: http://127.0.0.1:5173/demo/#/projects/lighting/code/repositories/flight-control-core/commits?branch=main | X38: 页面可稳定访问；主要交互可操作；刷新和页面跳转后数据语义一致。 | Y38: 需防止后续修改破坏跨页面数据一致性。 | Z38: 已完成并通过本地类型、构建与页面回归。 | AA38: 通过 | AB38: 46246 | AC38: 46246
A39: DEMO-035 | B39: 代码仓库 | C39: 提交 | D39: 提交详情与变更文件 | E39: 新功能 | F39: 是 | G39: Demo 模拟 | H39: 查看单次提交说明、关联请求、文件列表和 diff。 | I39: 跨部门推广规划 | J39: 产品、研发 | K39: P0 | L39: 已规划 | M39: L0 占位可达 | N39: L3 数据联动 | O39: 当前导航可达，使用通用占位页面。 | P39: 补齐关键场景、示例数据和核心交互。 | Q39: 待认领 | R39: 产品、设计、前端 | S39: v0.2 | T39: 建议排期 | U39: 46262 | V39: https://www.figma.com/design/AH5UD6NGdbtqy2z4o9k7QW/%E8%BD%AF%E4%BB%B6%E5%B7%A5%E5%8E%82?node-id=486-5192 | X39: 点击提交标题进入详情；变更文件、增删统计、关联合并请求与文件 diff 数据一致。 | Y39: 需确认部门共识与设计稿；仅模拟核心流程，不建设真实后端。 | Z39: 待评审范围与负责人。 | AA39: 未开始 | AC39: 46246
A40: DEMO-036 | B40: 代码仓库 | C40: 分支 | D40: 分支列表与真实计数 | E40: 现有能力 | F40: 是 | G40: UI 交互 + 数据联动 | H40: 查看分支状态、更新人、合并请求和领先／滞后。 | I40: 现有 Demo 实现 | J40: 产品、研发、设计 | K40: P0 | L40: 已完成 | M40: L3 数据联动 | N40: L3 数据联动 | O40: 已完成页面、关键交互和示例数据联动。 | P40: 纳入回归清单，持续根据部门反馈微调。 | Q40: Demo 小组 | R40: 产品、设计、前端 | S40: v0.1 | T40: 已确认 | U40: 46246 | V40: https://www.figma.com/design/AH5UD6NGdbtqy2z4o9k7QW/%E8%BD%AF%E4%BB%B6%E5%B7%A5%E5%8E%82?node-id=494-33747 | W40: http://127.0.0.1:5173/demo/#/projects/lighting/code/repositories/flight-control-core/branches | X40: 页面可稳定访问；主要交互可操作；刷新和页面跳转后数据语义一致。 | Y40: 需防止后续修改破坏跨页面数据一致性。 | Z40: 已完成并通过本地类型、构建与页面回归。 | AA40: 通过 | AB40: 46246 | AC40: 46246
A41: DEMO-037 | B41: 代码仓库 | C41: 分支 | D41: 新建分支弹窗 | E41: 现有能力 | F41: 否 | G41: UI 交互 | H41: 模拟从指定来源创建分支并反馈成功。 | I41: 现有 Demo 实现 | J41: 产品、研发、设计 | K41: P1 | L41: 已完成 | M41: L3 数据联动 | N41: L3 数据联动 | O41: 已完成页面、关键交互和示例数据联动。 | P41: 纳入回归清单，持续根据部门反馈微调。 | Q41: Demo 小组 | R41: 产品、设计、前端 | S41: v0.1 | T41: 已确认 | U41: 46246 | V41: https://www.figma.com/design/AH5UD6NGdbtqy2z4o9k7QW/%E8%BD%AF%E4%BB%B6%E5%B7%A5%E5%8E%82?node-id=524-35535 | W41: http://127.0.0.1:5173/demo/#/projects/lighting/code/repositories/flight-control-core/branches | X41: 页面可稳定访问；主要交互可操作；刷新和页面跳转后数据语义一致。 | Y41: 需防止后续修改破坏跨页面数据一致性。 | Z41: 已完成并通过本地类型、构建与页面回归。 | AA41: 通过 | AB41: 46246 | AC41: 46246
...

Sheet 枚举字典
A1: 状态 | B1: 优先级 | C1: 类型 | D1: 核心演示路径 | E1: 实现边界 | F1: 成熟度 | G1: 排期状态 | H1: 验收结果
A2: 待评估 | B2: P0 | C2: 现有能力 | D2: 是 | E2: 静态展示 | F2: L0 占位可达 | G2: 已确认 | H2: 未开始
A3: 已规划 | B3: P1 | C3: 新功能 | D3: 否 | E3: UI 交互 | F3: L1 静态展示 | G3: 建议排期 | H3: 待验收
A4: 设计中 | B4: P2 | C4: 体验优化 | E4: UI 交互 + 本地状态 | F4: L2 可交互 | G4: 待排期 | H4: 通过
A5: 开发中 | B5: P3 | C5: 数据完善 | E5: UI 交互 + 数据联动 | F5: L3 数据联动 | G5: 不排期 | H5: 需修改
A6: 待验收 | C6: 内容补充 | E6: Demo 模拟 | F6: L4 端到端叙事 | H6: 不适用
A7: 已完成 | C7: Bug | E7: 协作机制
A8: 已暂停 | C8: 协作治理 | E8: 数据规范
A9: 不采纳

Sheet 里程碑
A1: Vision Demo 建议里程碑
A2: v0.2 及以后日期为初版建议，需要在路线图评审中确认。
A4: 版本 | B4: 主题 | C4: 建议完成时间 | D4: 排期状态 | E4: 主要范围 | F4: 里程碑验收目标
A5: v0.1 | B5: 仓库场景基线 | C5: 46246 | D5: 已完成 | E5: 项目壳层、统一仓库数据、文件浏览、追溯、历史、提交、分支、标签、合并请求列表、应用管理基础。 | F5: 形成可用于内部评审的代码仓库主路径。
A6: v0.2 | B6: 仓库评审闭环 | C6: 46262 | D6: 建议排期 | E6: 提交详情、文件 diff、合并请求详情、协作反馈、使用指南、数据标准。 | F6: 仓库从浏览扩展到变更评审闭环。
A7: v0.3 | B7: 研发协同链路 | C7: 46283 | D7: 建议排期 | E7: 需求列表与详情、代码质量、流水线列表与运行详情、新建合并请求。 | F7: 打通需求—代码—构建的核心叙事。
A8: v0.4 | B8: 交付与验证链路 | C8: 46311 | D8: 建议排期 | E8: 制品、部署编排、环境、测试计划、用例、缺陷与发布历史。 | F8: 打通构建—制品—部署—测试。
A9: v1.0 | B9: 跨部门试点版 | C9: 46325 | D9: 建议排期 | E9: 端到端追溯、关键统计、治理能力、试点反馈闭环。 | F9: 支持多个部门围绕同一 Demo 独立沟通协作。

Sheet 字段说明
A1: 路线图字段说明
A2: 字段以跨部门可理解、可筛选、可验收为原则。
A4: 字段 | B4: 建议类型 | C4: 填写说明 | D4: 要求
A5: 功能编号 | B5: 自动编号 | C5: 稳定引用功能条目，会议和反馈中优先使用编号。 | D5: 必填
A6: 一级模块 | B6: 单选 | C6: 项目级能力域，如代码仓库、流水线、部署管理。 | D6: 必填
A7: 二级模块 | B7: 单选／文本 | C7: 一级模块下的功能分区。 | D7: 必填
A8: 功能名称 | B8: 单行文本 | C8: 使用动宾结构，描述明确可验收的能力。 | D8: 必填
A9: 类型 | B9: 单选 | C9: 区分现有能力、新功能、体验优化、数据完善等。 | D9: 必填
A10: 核心演示路径 | B10: 是／否 | C10: 是否属于跨部门演示必须打通的主路径。 | D10: 必填
A11: 实现边界 | B11: 单选 | C11: 明确仅做静态、交互、数据联动或协作机制，防止演变成真实后台项目。 | D11: 必填
A12: 使用场景与价值 | B12: 多行文本 | C12: 解释该功能帮助谁完成什么沟通任务。 | D12: 必填
A13: 需求来源 | B13: 文本 | C13: 记录设计稿、现有实现、部门诉求或路线图规划。 | D13: 建议
A14: 需求部门 | B14: 多选文本 | C14: 标识关注和受益部门，用中文顿号分隔。 | D14: 建议
A15: 优先级 | B15: 单选 | C15: P0 主路径阻塞；P1 高价值；P2 增强；P3 可延后。 | D15: 必填
... A33: 最后更新时间 | B33: 自动日期 | C33: 判断信息是否陈旧。 | D33: 必填
